ERROR:app:Exception on /api/portfolios/20 [GET]
Traceback (most recent call last):
  File "C:\Users\vpjd8\PycharmProjects\StockPredictorBackend\.venv\Lib\site-packages\flask\app.py", line 1511, in wsgi_app
    response = self.full_dispatch_request()
               ^^^^^^^^^^^^^^^^^^^^^^^^^^^^
  File "C:\Users\vpjd8\PycharmProjects\StockPredictorBackend\.venv\Lib\site-packages\flask\app.py", line 919, in full_dispatch_request
    rv = self.handle_user_exception(e)
         ^^^^^^^^^^^^^^^^^^^^^^^^^^^^^
  File "C:\Users\vpjd8\PycharmProjects\StockPredictorBackend\.venv\Lib\site-packages\flask_cors\extension.py", line 176, in wrapped_function
    return cors_after_request(app.make_response(f(*args, **kwargs)))
                                                ^^^^^^^^^^^^^^^^^^
  File "C:\Users\vpjd8\PycharmProjects\StockPredictorBackend\.venv\Lib\site-packages\flask\app.py", line 917, in full_dispatch_request
    rv = self.dispatch_request()
         ^^^^^^^^^^^^^^^^^^^^^^^
  File "C:\Users\vpjd8\PycharmProjects\StockPredictorBackend\.venv\Lib\site-packages\flask\app.py", line 902, in dispatch_request
    return self.ensure_sync(self.view_functions[rule.endpoint])(**view_args)  # type: ignore[no-any-return]
           ^^^^^^^^^^^^^^^^^^^^^^^^^^^^^^^^^^^^^^^^^^^^^^^^^^^^^^^^^^^^^^^^^
  File "C:\Users\vpjd8\PycharmProjects\StockPredictorBackend\.venv\Lib\site-packages\flask_login\utils.py", line 290, in decorated_view
    return current_app.ensure_sync(func)(*args, **kwargs)
           ^^^^^^^^^^^^^^^^^^^^^^^^^^^^^^^^^^^^^^^^^^^^^^
  File "C:\Users\vpjd8\PycharmProjects\StockPredictorBackend\routes.py", line 254, in get_portfolio
    @app.route('/api/portfolios/<int:portfolio_id>/analytics', methods=['GET'])
     ^^^^^^^^^^^^^^^^^^^^^^^^^^^^^^^^^^^^^^^^^^^^^^^^^^^^^^^^^^^^^^^^^^^^^^^^^^
  File "C:\Users\vpjd8\PycharmProjects\StockPredictorBackend\.venv\Lib\site-packages\flask\sansio\scaffold.py", line 46, in wrapper_func
    self._check_setup_finished(f_name)
  File "C:\Users\vpjd8\PycharmProjects\StockPredictorBackend\.venv\Lib\site-packages\flask\sansio\app.py", line 415, in _check_setup_finished
    raise AssertionError(
AssertionError: The setup method 'route' can no longer be called on the application. It has already handled its first request, any changes will not be applied consistently.
Make sure all imports, decorators, functions, etc. needed to set up the application are done before running it.
